<?xml version='1.0'?>
<sdf version='1.4'>
  <model name="techtrix_robot">
  	<static>false</static>
  	
  	<!-- We create the initial box of the robot -->
	 	<link name='chassis'>
	    <pose>0 0 .1 0 0 0</pose>

	    <collision name='collision'>
	    	<pose>0.2 0 0 0 0 0</pose>
	    
	      <geometry>
	        <box>
	          <size>1.1 1 1.5</size>
	        </box>
	      </geometry>
	    </collision>

     <visual name='visual'>
     		<!-- Somehow the model is also way too high, so we move it down -->
     		<pose>0 0 -1.45 0 0 0</pose>
     		
       <geometry>
         <mesh>
         		<uri>model://techtrix_robot/meshes/model.dae</uri>
         		<!-- The original model is too big -->
         		<scale>0.2 0.2 0.2</scale>
         </mesh>
       </geometry>
     </visual>
     
     <!-- Add the caster -->
	           
     <collision name='caster_collision'>
			   <pose>0.25 0 -0.7 0 0 0</pose>
			   <geometry>
			       <sphere>
			       <radius>.05</radius>
			     </sphere>
			   </geometry>

			   <surface>
			     <friction>
			       <ode>
			         <mu>0</mu>
			         <mu2>0</mu2>
			         <slip1>1.0</slip1>
			         <slip2>1.0</slip2>
			       </ode>
			     </friction>
			   </surface>
     </collision>
     
     <!-- The caster is only to keep equlibrium in the model, so we don't show it -->

     <!-- <visual name='caster_visual'>
							<pose>-0.15 0 -0.05 0 0 0</pose>
							<geometry>
									<sphere>
								<radius>.05</radius>
									</sphere>
							</geometry>
     </visual> -->
	 	</link>
	 	
	 	<!-- Add the wheels -->
		 	
	 	<link name="left_back_wheel">
      <pose>-0.1 0.5 -0.6 0 1.5707 1.5707</pose>
      <collision name="collision">
        <geometry>
          <cylinder>
            <radius>.1</radius>
            <length>.05</length>
          </cylinder>
        </geometry>
      </collision>
      <!-- <visual name="visual">
        <geometry>
          <cylinder>
            <radius>.1</radius>
            <length>.05</length>
          </cylinder>
        </geometry>
      </visual> -->
    </link>
    
			<link name="left_front_wheel">
      <pose>0.55 0.5 -0.6 0 1.5707 1.5707</pose>
      <collision name="collision">
        <geometry>
          <cylinder>
            <radius>.1</radius>
            <length>.05</length>
          </cylinder>
        </geometry>
      </collision>
      <!-- <visual name="visual">
        <geometry>
          <cylinder>
            <radius>.1</radius>
            <length>.05</length>
          </cylinder>
        </geometry>
      </visual> -->
    </link>
      
    <!-- We can make a right wheel by copying the left wheel, and adjusting the wheel link's pose -->
    
    <link name="right_back_wheel">
      <pose>-0.1 -0.5 -0.6 0 1.5707 1.5707</pose>
      <collision name="collision">
        <geometry>
          <cylinder>
            <radius>.1</radius>
            <length>.05</length>
          </cylinder>
        </geometry>
      </collision>
      <!-- <visual name="visual">
        <geometry>
          <cylinder>
            <radius>.1</radius>
            <length>.05</length>
          </cylinder>
        </geometry>
      </visual> -->
    </link>
    
    <link name="right_front_wheel">
      <pose>0.55 -0.5 -0.6 0 1.5707 1.5707</pose>
      <collision name="collision">
        <geometry>
          <cylinder>
            <radius>.1</radius>
            <length>.05</length>
          </cylinder>
        </geometry>
      </collision>
      <!-- <visual name="visual">
        <geometry>
          <cylinder>
            <radius>.1</radius>
            <length>.05</length>
          </cylinder>
        </geometry>
      </visual> -->
    </link>
    
    <!-- Add four hinge joints for the left and right wheels -->
    <!-- The four joints rotate about the y axis <xyz>0 1 0</xyz>, and connect each wheel to the chassis -->
    
    <joint type="revolute" name="left_back_wheel_hinge">
	    <pose>0 0 -0.03 0 0 0</pose>
	    <child>left_back_wheel</child>
	    <parent>chassis</parent>
	    <axis>
	      <xyz>0 1 0</xyz>
	    </axis>
    </joint>
    
    <joint type="revolute" name="left_front_wheel_hinge">
	    <pose>0 0 -0.03 0 0 0</pose>
	    <child>left_front_wheel</child>
	    <parent>chassis</parent>
	    <axis>
	      <xyz>0 1 0</xyz>
	    </axis>
    </joint>
    
    <joint type="revolute" name="right_back_wheel_hinge">
     <pose>0 0 0.03 0 0 0</pose>
     <child>right_back_wheel</child>
     <parent>chassis</parent>
     <axis>
       <xyz>0 1 0</xyz>
     </axis>
    </joint>

    <joint type="revolute" name="right_front_wheel_hinge">
     <pose>0 0 0.03 0 0 0</pose>
     <child>right_front_wheel</child>
     <parent>chassis</parent>
     <axis>
       <xyz>0 1 0</xyz>
     </axis>
    </joint>
  </model>
</sdf>
